Workbook

Sheet Students
A1: student_id | B1: fullName | C1: gender | D1: birthdate | E1: age | F1: course | G1: contactNumber | H1: email
A2: 100000 | B2: Alex Santos | C2: Male | D2: 2006-01-10 | E2: =IF(D2="","",DATEDIF(D2,TODAY(),"Y")) -> 20 | F2: BSIT | G2: 09277125461 | H2: student100000@torneros.edu.ph
A3: 100001 | B3: Alex Garcia | C3: Female | D3: 2005-02-11 | E3: =IF(D3="","",DATEDIF(D3,TODAY(),"Y")) -> 20 | F3: BSCS | G3: 09761393220 | H3: student100001@torneros.edu.ph
A4: 100002 | B4: Alex Reyes | C4: Male | D4: 2004-03-12 | E4: =IF(D4="","",DATEDIF(D4,TODAY(),"Y")) -> 21 | F4: BSIT | G4: 09189795489 | H4: student100002@torneros.edu.ph
A5: 100003 | B5: Alex Cruz | C5: Female | D5: 2003-04-13 | E5: =IF(D5="","",DATEDIF(D5,TODAY(),"Y")) -> 22 | F5: BSIT | G5: 09730730038 | H5: student100003@torneros.edu.ph
A6: 100004 | B6: Alex Lopez | C6: Male | D6: 2002-05-14 | E6: =IF(D6="","",DATEDIF(D6,TODAY(),"Y")) -> 23 | F6: BSCS | G6: 09947623901 | H6: student100004@torneros.edu.ph
A7: 100005 | B7: Alex Flores | C7: Female | D7: 2006-06-15 | E7: =IF(D7="","",DATEDIF(D7,TODAY(),"Y")) -> 19 | F7: BSIT | G7: 09217809857 | H7: student100005@torneros.edu.ph
A8: 100006 | B8: Alex Ramos | C8: Male | D8: 2005-07-16 | E8: =IF(D8="","",DATEDIF(D8,TODAY(),"Y")) -> 20 | F8: BSIT | G8: 09713564024 | H8: student100006@torneros.edu.ph
A9: 100007 | B9: Alex Gonzales | C9: Female | D9: 2004-08-17 | E9: =IF(D9="","",DATEDIF(D9,TODAY(),"Y")) -> 21 | F9: BSCS | G9: 09367870536 | H9: student100007@torneros.edu.ph
A10: 100008 | B10: Alex Torres | C10: Male | D10: 2003-09-18 | E10: =IF(D10="","",DATEDIF(D10,TODAY(),"Y")) -> 22 | F10: BSIT | G10: 09171841123 | H10: student100008@torneros.edu.ph
A11: 100009 | B11: Alex Rivera | C11: Female | D11: 2002-01-19 | E11: =IF(D11="","",DATEDIF(D11,TODAY(),"Y")) -> 24 | F11: BSIT | G11: 09399139917 | H11: student100009@torneros.edu.ph
A12: 100010 | B12: Alex Mendoza | C12: Male | D12: 2006-02-10 | E12: =IF(D12="","",DATEDIF(D12,TODAY(),"Y")) -> 19 | F12: BSCS | G12: 09468223775 | H12: student100010@torneros.edu.ph
A13: 100011 | B13: Alex Aquino | C13: Female | D13: 2005-03-11 | E13: =IF(D13="","",DATEDIF(D13,TODAY(),"Y")) -> 20 | F13: BSIT | G13: 09266810976 | H13: student100011@torneros.edu.ph
... A51: 100049 | B51: Dina Garcia | C51: Female | D51: 2002-05-19 | E51: =IF(D51="","",DATEDIF(D51,TODAY(),"Y")) -> 23 | F51: BSCS | G51: 09779226774 | H51: student100049@torneros.edu.ph

Sheet Subjects
A1: student_name | B1: subject_name | C1: prelim | D1: midterm | E1: prefinal | F1: finals | G1: average | H1: GPA | I1: remarks | J1: year_level | K1: semester
A2: =IFERROR(Students!B13, "Student Not Found") -> Alex Aquino | B2: Artificial Intelligence | C2: 75 | D2: 70 | E2: 70 | F2: 70 | G2: =AVERAGE(C2:F2) -> 71.25 | H2: =IF(G2>=96,1,IF(G2>=94,1.25,IF(G2>=91,1.5,IF(G2>=89,1.75,IF(G2>=86,2,IF(G2>=83,2.25,IF(G2>=80,2.5,IF(G2>=77,2.75,IF(G2>=75,3,5))))))))) -> 5 | I2: =IF(H2<=3,"PASSED","FAILED") -> FAILED | J2: 2023-2024 | K2: FIRST
A3: Alex Aquino | B3: Data Structures | C3: 85 | D3: 98 | E3: 77 | F3: 86 | G3: =AVERAGE(C3:F3) -> 86.5 | H3: =IF(G3>=96,1,IF(G3>=94,1.25,IF(G3>=91,1.5,IF(G3>=89,1.75,IF(G3>=86,2,IF(G3>=83,2.25,IF(G3>=80,2.5,IF(G3>=77,2.75,IF(G3>=75,3,5))))))))) -> 2 | I3: =IF(H3<=3,"PASSED","FAILED") -> PASSED | J3: 2023-2024 | K3: FIRST
A4: Alex Aquino | B4: Database Systems | C4: 97 | D4: 98 | E4: 96 | F4: 78 | G4: =AVERAGE(C4:F4) -> 92.25 | H4: =IF(G4>=96,1,IF(G4>=94,1.25,IF(G4>=91,1.5,IF(G4>=89,1.75,IF(G4>=86,2,IF(G4>=83,2.25,IF(G4>=80,2.5,IF(G4>=77,2.75,IF(G4>=75,3,5))))))))) -> 1.5 | I4: =IF(H4<=3,"PASSED","FAILED") -> PASSED | J4: 2023-2024 | K4: SECOND
A5: Alex Aquino | B5: Discrete Mathematics | C5: 79 | D5: 81 | E5: 76 | F5: 98 | G5: =AVERAGE(C5:F5) -> 83.5 | H5: =IF(G5>=96,1,IF(G5>=94,1.25,IF(G5>=91,1.5,IF(G5>=89,1.75,IF(G5>=86,2,IF(G5>=83,2.25,IF(G5>=80,2.5,IF(G5>=77,2.75,IF(G5>=75,3,5))))))))) -> 2.25 | I5: =IF(H5<=3,"PASSED","FAILED") -> PASSED | J5: 2025-2026 | K5: FIRST
A6: Alex Aquino | B6: Introduction to Computing | C6: 80 | D6: 90 | E6: 93 | F6: 96 | G6: =AVERAGE(C6:F6) -> 89.75 | H6: =IF(G6>=96,1,IF(G6>=94,1.25,IF(G6>=91,1.5,IF(G6>=89,1.75,IF(G6>=86,2,IF(G6>=83,2.25,IF(G6>=80,2.5,IF(G6>=77,2.75,IF(G6>=75,3,5))))))))) -> 1.75 | I6: =IF(H6<=3,"PASSED","FAILED") -> PASSED | J6: 2023-2024 | K6: FIRST
A7: Alex Aquino | B7: Mobile App Dev | C7: 91 | D7: 86 | E7: 92 | F7: 89 | G7: =AVERAGE(C7:F7) -> 89.5 | H7: =IF(G7>=96,1,IF(G7>=94,1.25,IF(G7>=91,1.5,IF(G7>=89,1.75,IF(G7>=86,2,IF(G7>=83,2.25,IF(G7>=80,2.5,IF(G7>=77,2.75,IF(G7>=75,3,5))))))))) -> 1.75 | I7: =IF(H7<=3,"PASSED","FAILED") -> PASSED | J7: 2023-2024 | K7: FIRST
A8: Alex Aquino | B8: Programming 1 | C8: 82 | D8: 76 | E8: 80 | F8: 80 | G8: =AVERAGE(C8:F8) -> 79.5 | H8: =IF(G8>=96,1,IF(G8>=94,1.25,IF(G8>=91,1.5,IF(G8>=89,1.75,IF(G8>=86,2,IF(G8>=83,2.25,IF(G8>=80,2.5,IF(G8>=77,2.75,IF(G8>=75,3,5))))))))) -> 2.75 | I8: =IF(H8<=3,"PASSED","FAILED") -> PASSED | J8: 2024-2025 | K8: SECOND
A9: Alex Aquino | B9: Software Engineering | C9: 89 | D9: 85 | E9: 78 | F9: 94 | G9: 86.5 | H9: =IF(G9>=96,1,IF(G9>=94,1.25,IF(G9>=91,1.5,IF(G9>=89,1.75,IF(G9>=86,2,IF(G9>=83,2.25,IF(G9>=80,2.5,IF(G9>=77,2.75,IF(G9>=75,3,5))))))))) -> 2 | I9: PASSED | J9: 2023-2024 | K9: FIRST
A10: Alex Aquino | B10: Web Development | C10: 89 | D10: 85 | E10: 78 | F10: 94 | G10: 86.5 | H10: =IF(G10>=96,1,IF(G10>=94,1.25,IF(G10>=91,1.5,IF(G10>=89,1.75,IF(G10>=86,2,IF(G10>=83,2.25,IF(G10>=80,2.5,IF(G10>=77,2.75,IF(G10>=75,3,5))))))))) -> 2 | I10: PASSED | J10: 2023-2024 | K10: FIRST
A11: =IFERROR(Students!B15, "Student Not Found") -> Alex Castro | B11: Artificial Intelligence | C11: 81 | D11: 88 | E11: 79 | F11: 90 | G11: =AVERAGE(C11:F11) -> 84.5 | H11: =IF(G11>=96,1,IF(G11>=94,1.25,IF(G11>=91,1.5,IF(G11>=89,1.75,IF(G11>=86,2,IF(G11>=83,2.25,IF(G11>=80,2.5,IF(G11>=77,2.75,IF(G11>=75,3,5))))))))) -> 2.25 | I11: =IF(H11<=3,"PASSED","FAILED") -> PASSED | J11: 2023-2024 | K11: SECOND
A12: Alex Castro | B12: Data Structures | C12: 75 | D12: 76 | E12: 94 | F12: 80 | G12: =AVERAGE(C12:F12) -> 81.25 | H12: =IF(G12>=96,1,IF(G12>=94,1.25,IF(G12>=91,1.5,IF(G12>=89,1.75,IF(G12>=86,2,IF(G12>=83,2.25,IF(G12>=80,2.5,IF(G12>=77,2.75,IF(G12>=75,3,5))))))))) -> 2.5 | I12: =IF(H12<=3,"PASSED","FAILED") -> PASSED | J12: 2023-2024 | K12: FIRST
A13: Alex Castro | B13: Database Systems | C13: 86 | D13: 88 | E13: 82 | F13: 80 | G13: =AVERAGE(C13:F13) -> 84 | H13: =IF(G13>=96,1,IF(G13>=94,1.25,IF(G13>=91,1.5,IF(G13>=89,1.75,IF(G13>=86,2,IF(G13>=83,2.25,IF(G13>=80,2.5,IF(G13>=77,2.75,IF(G13>=75,3,5))))))))) -> 2.25 | I13: =IF(H13<=3,"PASSED","FAILED") -> PASSED | J13: 2023-2024 | K13: SECOND
A14: Alex Castro | B14: Discrete Mathematics | C14: 87 | D14: 98 | E14: 86 | F14: 91 | G14: =AVERAGE(C14:F14) -> 90.5 | H14: =IF(G14>=96,1,IF(G14>=94,1.25,IF(G14>=91,1.5,IF(G14>=89,1.75,IF(G14>=86,2,IF(G14>=83,2.25,IF(G14>=80,2.5,IF(G14>=77,2.75,IF(G14>=75,3,5))))))))) -> 1.75 | I14: =IF(H14<=3,"PASSED","FAILED") -> PASSED | J14: 2023-2024 | K14: FIRST
A15: Alex Castro | B15: Introduction to Computing | C15: 89 | D15: 82 | E15: 76 | F15: 83 | G15: =AVERAGE(C15:F15) -> 82.5 | H15: =IF(G15>=96,1,IF(G15>=94,1.25,IF(G15>=91,1.5,IF(G15>=89,1.75,IF(G15>=86,2,IF(G15>=83,2.25,IF(G15>=80,2.5,IF(G15>=77,2.75,IF(G15>=75,3,5))))))))) -> 2.5 | I15: =IF(H15<=3,"PASSED","FAILED") -> PASSED | J15: 2024-2025 | K15: SECOND
A16: Alex Castro | B16: Mobile App Dev | C16: 94 | D16: 81 | E16: 97 | F16: 99 | G16: =AVERAGE(C16:F16) -> 92.75 | H16: =IF(G16>=96,1,IF(G16>=94,1.25,IF(G16>=91,1.5,IF(G16>=89,1.75,IF(G16>=86,2,IF(G16>=83,2.25,IF(G16>=80,2.5,IF(G16>=77,2.75,IF(G16>=75,3,5))))))))) -> 1.5 | I16: =IF(H16<=3,"PASSED","FAILED") -> PASSED | J16: 2025-2026 | K16: SECOND
A17: Alex Castro | B17: Programming 1 | C17: 91 | D17: 98 | E17: 91 | F17: 96 | G17: =AVERAGE(C17:F17) -> 94 | H17: =IF(G17>=96,1,IF(G17>=94,1.25,IF(G17>=91,1.5,IF(G17>=89,1.75,IF(G17>=86,2,IF(G17>=83,2.25,IF(G17>=80,2.5,IF(G17>=77,2.75,IF(G17>=75,3,5))))))))) -> 1.25 | I17: =IF(H17<=3,"PASSED","FAILED") -> PASSED | J17: 2023-2024 | K17: FIRST
A18: Alex Castro | B18: Software Engineering | C18: 92 | D18: 75 | E18: 75 | F18: 98 | G18: 85 | H18: =IF(G18>=96,1,IF(G18>=94,1.25,IF(G18>=91,1.5,IF(G18>=89,1.75,IF(G18>=86,2,IF(G18>=83,2.25,IF(G18>=80,2.5,IF(G18>=77,2.75,IF(G18>=75,3,5))))))))) -> 2.25 | I18: PASSED | J18: 2025-2026 | K18: FIRST
A19: Alex Castro | B19: Web Development | C19: 92 | D19: 75 | E19: 75 | F19: 98 | G19: 85 | H19: =IF(G19>=96,1,IF(G19>=94,1.25,IF(G19>=91,1.5,IF(G19>=89,1.75,IF(G19>=86,2,IF(G19>=83,2.25,IF(G19>=80,2.5,IF(G19>=77,2.75,IF(G19>=75,3,5))))))))) -> 2.25 | I19: PASSED | J19: 2025-2026 | K19: FIRST
A20: =IFERROR(Students!B5, "Student Not Found") -> Alex Cruz | B20: Artificial Intelligence | C20: 76 | D20: 93 | E20: 83 | F20: 80 | G20: =AVERAGE(C20:F20) -> 83 | H20: =IF(G20>=96,1,IF(G20>=94,1.25,IF(G20>=91,1.5,IF(G20>=89,1.75,IF(G20>=86,2,IF(G20>=83,2.25,IF(G20>=80,2.5,IF(G20>=77,2.75,IF(G20>=75,3,5))))))))) -> 2.25 | I20: =IF(H20<=3,"PASSED","FAILED") -> PASSED | J20: 2024-2025 | K20: SECOND
A21: Alex Cruz | B21: Data Structures | C21: 92 | D21: 86 | E21: 96 | F21: 87 | G21: =AVERAGE(C21:F21) -> 90.25 | H21: =IF(G21>=96,1,IF(G21>=94,1.25,IF(G21>=91,1.5,IF(G21>=89,1.75,IF(G21>=86,2,IF(G21>=83,2.25,IF(G21>=80,2.5,IF(G21>=77,2.75,IF(G21>=75,3,5))))))))) -> 1.75 | I21: =IF(H21<=3,"PASSED","FAILED") -> PASSED | J21: 2024-2025 | K21: SECOND
A22: Alex Cruz | B22: Database Systems | C22: 84 | D22: 95 | E22: 99 | F22: 81 | G22: =AVERAGE(C22:F22) -> 89.75 | H22: =IF(G22>=96,1,IF(G22>=94,1.25,IF(G22>=91,1.5,IF(G22>=89,1.75,IF(G22>=86,2,IF(G22>=83,2.25,IF(G22>=80,2.5,IF(G22>=77,2.75,IF(G22>=75,3,5))))))))) -> 1.75 | I22: =IF(H22<=3,"PASSED","FAILED") -> PASSED | J22: 2023-2024 | K22: SECOND
A23: Alex Cruz | B23: Discrete Mathematics | C23: 83 | D23: 89 | E23: 96 | F23: 81 | G23: =AVERAGE(C23:F23) -> 87.25 | H23: =IF(G23>=96,1,IF(G23>=94,1.25,IF(G23>=91,1.5,IF(G23>=89,1.75,IF(G23>=86,2,IF(G23>=83,2.25,IF(G23>=80,2.5,IF(G23>=77,2.75,IF(G23>=75,3,5))))))))) -> 2 | I23: =IF(H23<=3,"PASSED","FAILED") -> PASSED | J23: 2023-2024 | K23: SECOND
A24: Alex Cruz | B24: Introduction to Computing | C24: 98 | D24: 86 | E24: 98 | F24: 98 | G24: =AVERAGE(C24:F24) -> 95 | H24: =IF(G24>=96,1,IF(G24>=94,1.25,IF(G24>=91,1.5,IF(G24>=89,1.75,IF(G24>=86,2,IF(G24>=83,2.25,IF(G24>=80,2.5,IF(G24>=77,2.75,IF(G24>=75,3,5))))))))) -> 1.25 | I24: =IF(H24<=3,"PASSED","FAILED") -> PASSED | J24: 2023-2024 | K24: FIRST
A25: Alex Cruz | B25: Mobile App Dev | C25: 81 | D25: 97 | E25: 80 | F25: 78 | G25: =AVERAGE(C25:F25) -> 84 | H25: =IF(G25>=96,1,IF(G25>=94,1.25,IF(G25>=91,1.5,IF(G25>=89,1.75,IF(G25>=86,2,IF(G25>=83,2.25,IF(G25>=80,2.5,IF(G25>=77,2.75,IF(G25>=75,3,5))))))))) -> 2.25 | I25: =IF(H25<=3,"PASSED","FAILED") -> PASSED | J25: 2024-2025 | K25: FIRST
A26: Alex Cruz | B26: Programming 1 | C26: 97 | D26: 75 | E26: 97 | F26: 90 | G26: =AVERAGE(C26:F26) -> 89.75 | H26: =IF(G26>=96,1,IF(G26>=94,1.25,IF(G26>=91,1.5,IF(G26>=89,1.75,IF(G26>=86,2,IF(G26>=83,2.25,IF(G26>=80,2.5,IF(G26>=77,2.75,IF(G26>=75,3,5))))))))) -> 1.75 | I26: =IF(H26<=3,"PASSED","FAILED") -> PASSED | J26: 2025-2026 | K26: SECOND
A27: Alex Cruz | B27: Software Engineering | C27: 82 | D27: 83 | E27: 91 | F27: 98 | G27: 88.5 | H27: =IF(G27>=96,1,IF(G27>=94,1.25,IF(G27>=91,1.5,IF(G27>=89,1.75,IF(G27>=86,2,IF(G27>=83,2.25,IF(G27>=80,2.5,IF(G27>=77,2.75,IF(G27>=75,3,5))))))))) -> 2 | I27: PASSED | J27: 2024-2025 | K27: SECOND
A28: Alex Cruz | B28: Web Development | C28: 82 | D28: 83 | E28: 91 | F28: 98 | G28: 88.5 | H28: =IF(G28>=96,1,IF(G28>=94,1.25,IF(G28>=91,1.5,IF(G28>=89,1.75,IF(G28>=86,2,IF(G28>=83,2.25,IF(G28>=80,2.5,IF(G28>=77,2.75,IF(G28>=75,3,5))))))))) -> 2 | I28: PASSED | J28: 2024-2025 | K28: SECOND
A29: =IFERROR(Students!B16, "Student Not Found") -> Alex Delos Reyes | B29: Artificial Intelligence | C29: 80 | D29: 80 | E29: 88 | F29: 87 | G29: =AVERAGE(C29:F29) -> 83.75 | H29: =IF(G29>=96,1,IF(G29>=94,1.25,IF(G29>=91,1.5,IF(G29>=89,1.75,IF(G29>=86,2,IF(G29>=83,2.25,IF(G29>=80,2.5,IF(G29>=77,2.75,IF(G29>=75,3,5))))))))) -> 2.25 | I29: =IF(H29<=3,"PASSED","FAILED") -> PASSED | J29: 2025-2026 | K29: FIRST
A30: Alex Delos Reyes | B30: Data Structures | C30: 87 | D30: 83 | E30: 77 | F30: 89 | G30: =AVERAGE(C30:F30) -> 84 | H30: =IF(G30>=96,1,IF(G30>=94,1.25,IF(G30>=91,1.5,IF(G30>=89,1.75,IF(G30>=86,2,IF(G30>=83,2.25,IF(G30>=80,2.5,IF(G30>=77,2.75,IF(G30>=75,3,5))))))))) -> 2.25 | I30: =IF(H30<=3,"PASSED","FAILED") -> PASSED | J30: 2024-2025 | K30: FIRST
A31: Alex Delos Reyes | B31: Database Systems | C31: 88 | D31: 93 | E31: 92 | F31: 98 | G31: =AVERAGE(C31:F31) -> 92.75 | H31: =IF(G31>=96,1,IF(G31>=94,1.25,IF(G31>=91,1.5,IF(G31>=89,1.75,IF(G31>=86,2,IF(G31>=83,2.25,IF(G31>=80,2.5,IF(G31>=77,2.75,IF(G31>=75,3,5))))))))) -> 1.5 | I31: =IF(H31<=3,"PASSED","FAILED") -> PASSED | J31: 2023-2024 | K31: FIRST
A32: Alex Delos Reyes | B32: Discrete Mathematics | C32: 93 | D32: 88 | E32: 93 | F32: 78 | G32: =AVERAGE(C32:F32) -> 88 | H32: =IF(G32>=96,1,IF(G32>=94,1.25,IF(G32>=91,1.5,IF(G32>=89,1.75,IF(G32>=86,2,IF(G32>=83,2.25,IF(G32>=80,2.5,IF(G32>=77,2.75,IF(G32>=75,3,5))))))))) -> 2 | I32: =IF(H32<=3,"PASSED","FAILED") -> PASSED | J32: 2024-2025 | K32: FIRST
A33: Alex Delos Reyes | B33: Introduction to Computing | C33: 86 | D33: 87 | E33: 84 | F33: 99 | G33: =AVERAGE(C33:F33) -> 89 | H33: =IF(G33>=96,1,IF(G33>=94,1.25,IF(G33>=91,1.5,IF(G33>=89,1.75,IF(G33>=86,2,IF(G33>=83,2.25,IF(G33>=80,2.5,IF(G33>=77,2.75,IF(G33>=75,3,5))))))))) -> 1.75 | I33: =IF(H33<=3,"PASSED","FAILED") -> PASSED | J33: 2023-2024 | K33: SECOND
A34: Alex Delos Reyes | B34: Mobile App Dev | C34: 86 | D34: 86 | E34: 98 | F34: 91 | G34: =AVERAGE(C34:F34) -> 90.25 | H34: =IF(G34>=96,1,IF(G34>=94,1.25,IF(G34>=91,1.5,IF(G34>=89,1.75,IF(G34>=86,2,IF(G34>=83,2.25,IF(G34>=80,2.5,IF(G34>=77,2.75,IF(G34>=75,3,5))))))))) -> 1.75 | I34: =IF(H34<=3,"PASSED","FAILED") -> PASSED | J34: 2023-2024 | K34: FIRST
A35: Alex Delos Reyes | B35: Programming 1 | C35: 83 | D35: 75 | E35: 77 | F35: 75 | G35: =AVERAGE(C35:F35) -> 77.5 | H35: =IF(G35>=96,1,IF(G35>=94,1.25,IF(G35>=91,1.5,IF(G35>=89,1.75,IF(G35>=86,2,IF(G35>=83,2.25,IF(G35>=80,2.5,IF(G35>=77,2.75,IF(G35>=75,3,5))))))))) -> 2.75 | I35: =IF(H35<=3,"PASSED","FAILED") -> PASSED | J35: 2024-2025 | K35: SECOND
A36: Alex Delos Reyes | B36: Software Engineering | C36: 79 | D36: 84 | E36: 87 | F36: 78 | G36: 82 | H36: =IF(G36>=96,1,IF(G36>=94,1.25,IF(G36>=91,1.5,IF(G36>=89,1.75,IF(G36>=86,2,IF(G36>=83,2.25,IF(G36>=80,2.5,IF(G36>=77,2.75,IF(G36>=75,3,5))))))))) -> 2.5 | I36: PASSED | J36: 2025-2026 | K36: FIRST
A37: Alex Delos Reyes | B37: Web Development | C37: 79 | D37: 84 | E37: 87 | F37: 78 | G37: 82 | H37: =IF(G37>=96,1,IF(G37>=94,1.25,IF(G37>=91,1.5,IF(G37>=89,1.75,IF(G37>=86,2,IF(G37>=83,2.25,IF(G37>=80,2.5,IF(G37>=77,2.75,IF(G37>=75,3,5))))))))) -> 2.5 | I37: PASSED | J37: 2025-2026 | K37: FIRST
A38: =IFERROR(Students!B7, "Student Not Found") -> Alex Flores | B38: Artificial Intelligence | C38: 75 | D38: 91 | E38: 80 | F38: 87 | G38: =AVERAGE(C38:F38) -> 83.25 | H38: =IF(G38>=96,1,IF(G38>=94,1.25,IF(G38>=91,1.5,IF(G38>=89,1.75,IF(G38>=86,2,IF(G38>=83,2.25,IF(G38>=80,2.5,IF(G38>=77,2.75,IF(G38>=75,3,5))))))))) -> 2.25 | I38: =IF(H38<=3,"PASSED","FAILED") -> PASSED | J38: 2024-2025 | K38: SECOND
A39: Alex Flores | B39: Data Structures | C39: 99 | D39: 85 | E39: 83 | F39: 87 | G39: =AVERAGE(C39:F39) -> 88.5 | H39: =IF(G39>=96,1,IF(G39>=94,1.25,IF(G39>=91,1.5,IF(G39>=89,1.75,IF(G39>=86,2,IF(G39>=83,2.25,IF(G39>=80,2.5,IF(G39>=77,2.75,IF(G39>=75,3,5))))))))) -> 2 | I39: =IF(H39<=3,"PASSED","FAILED") -> PASSED | J39: 2023-2024 | K39: FIRST
A40: Alex Flores | B40: Database Systems | C40: 94 | D40: 80 | E40: 88 | F40: 90 | G40: =AVERAGE(C40:F40) -> 88 | H40: =IF(G40>=96,1,IF(G40>=94,1.25,IF(G40>=91,1.5,IF(G40>=89,1.75,IF(G40>=86,2,IF(G40>=83,2.25,IF(G40>=80,2.5,IF(G40>=77,2.75,IF(G40>=75,3,5))))))))) -> 2 | I40: =IF(H40<=3,"PASSED","FAILED") -> PASSED | J40: 2024-2025 | K40: SECOND
...
